Workbook
Name A: Expenses!$1:$1048576
Name Balance: Setup!$C$11

Sheet Setup
B1: Annual budget tracker
B3: Plan and track your business income and expenses for the entire year.
B4: How to use this template
A5: 1. | B5: Get started by entering your starting balance below.
A6: 2. | B6: Then, fill out the 'Expenses' and 'Income' tabs.
A7: 3. | B7: Feel free to rename or delete categories in these tabs. Your changes will automatically be reflected on the 'Summary' tab, which shows an overview of your projected/actual spending.
B10: Configure
B11: Starting balance: | C11: 0 | D11: Lihat Tabel di Sheet Asumsi & SBU

Sheet Income
B1: UNIT / PRODI | E1: Pendapatan | F1: 45839 | G1: 45870 | H1: 45901 | I1: 45931 | J1: 45962 | K1: 45992 | L1: 46023 | M1: 46054 | N1: 46082 | O1: 46113 | P1: 46143 | Q1: 46174 | R1: Total | S1: Average
B2: Pendapatan Operasional | E2: Total Bulanan | F2: =SUM(F3:F5) -> 0 | G2: =SUM(G3:G5) -> 0 | H2: =SUM(H3:H5) -> 0 | I2: =SUM(I3:I5) -> 0 | J2: =SUM(J3:J5) -> 0 | K2: =SUM(K3:K5) -> 0 | L2: =SUM(L3:L5) -> 0 | M2: =SUM(M3:M5) -> 0 | ... Q2: =SUM(Q3:Q5) -> 0 | R2: =SUM(F2:Q2) -> 0 | S2: =IFERROR(AVERAGE(F2:Q2), "0") -> 0
E3: Dana Pengembangan | F3: 0 | G3: 0 | H3: 0 | I3: 0 | J3: 0 | K3: 0 | L3: 0 | M3: 0 | N3: 0 | O3: 0 | P3: 0 | Q3: 0 | R3: =SUM(F3:Q3) -> 0 | S3: =IFERROR(AVERAGE(F3:Q3), "0") -> 0
E4: Dana Kuliah (SPP) | F4: 0 | G4: 0 | H4: 0 | I4: 0 | J4: 0 | K4: 0 | L4: 0 | M4: 0 | N4: 0 | O4: 0 | P4: 0 | Q4: 0 | R4: =SUM(F4:Q4) -> 0 | S4: =IFERROR(AVERAGE(F4:Q4), "0") -> 0
E5: Dana Uang Kuliah Tunggal | F5: 0 | G5: 0 | H5: 0 | I5: 0 | J5: 0 | K5: 0 | L5: 0 | M5: 0 | N5: 0 | O5: 0 | P5: 0 | Q5: 0 | R5: =SUM(F5:Q5) -> 0 | S5: =IFERROR(AVERAGE(F5:Q5), "0") -> 0
B8: Pendapatan Lain-Lain | E8: Total Bulanan | F8: =SUM(F9:F29) -> 0 | G8: =SUM(G9:G29) -> 0 | H8: =SUM(H9:H29) -> 0 | I8: =SUM(I9:I29) -> 0 | J8: =SUM(J9:J29) -> 0 | K8: =SUM(K9:K29) -> 0 | L8: =SUM(L9:L29) -> 0 | M8: =SUM(M9:M29) -> 0 | ... Q8: =SUM(Q9:Q29) -> 0 | R8: =SUM(F8:Q8) -> 0 | S8: =IFERROR(AVERAGE(F8:Q8), "0") -> 0
E9: Pendaftaran Mahasiswa Baru | F9: 0 | G9: 0 | H9: 0 | I9: 0 | J9: 0 | K9: 0 | L9: 0 | M9: 0 | N9: 0 | O9: 0 | P9: 0 | Q9: 0 | R9: =SUM(F9:Q9) -> 0 | S9: =IFERROR(AVERAGE(F9:Q9), "0") -> 0
E10: Pendapatan Virtual Account | F10: 0 | G10: 0 | H10: 0 | I10: 0 | J10: 0 | K10: 0 | L10: 0 | M10: 0 | N10: 0 | O10: 0 | P10: 0 | Q10: 0 | R10: =SUM(F10:Q10) -> 0 | S10: =IFERROR(AVERAGE(F10:Q10), "0") -> 0
E11: Her-registrasi Semester | F11: 0 | G11: 0 | H11: 0 | I11: 0 | J11: 0 | K11: 0 | L11: 0 | M11: 0 | N11: 0 | O11: 0 | P11: 0 | Q11: 0 | R11: =SUM(F11:Q11) -> 0 | S11: =IFERROR(AVERAGE(F11:Q11), "0") -> 0
E12: Denda Perpustakaan | F12: 0 | G12: 0 | H12: 0 | I12: 0 | J12: 0 | K12: 0 | L12: 0 | M12: 0 | N12: 0 | O12: 0 | P12: 0 | Q12: 0 | R12: =SUM(F12:Q12) -> 0 | S12: =IFERROR(AVERAGE(F12:Q12), "0") -> 0
E13: Semester Antara | F13: 0 | G13: 0 | H13: 0 | I13: 0 | J13: 0 | K13: 0 | L13: 0 | M13: 0 | N13: 0 | O13: 0 | P13: 0 | Q13: 0 | R13: =SUM(F13:Q13) -> 0 | S13: =IFERROR(AVERAGE(F13:Q13), "0") -> 0
E14: KKN | F14: 0 | G14: 0 | H14: 0 | I14: 0 | J14: 0 | K14: 0 | L14: 0 | M14: 0 | N14: 0 | O14: 0 | P14: 0 | Q14: 0 | R14: =SUM(F14:Q14) -> 0 | S14: =IFERROR(AVERAGE(F14:Q14), "0") -> 0
E15: Sidang Skripsi/TA | F15: 0 | G15: 0 | H15: 0 | I15: 0 | J15: 0 | K15: 0 | L15: 0 | M15: 0 | N15: 0 | O15: 0 | P15: 0 | Q15: 0 | R15: =SUM(F15:Q15) -> 0 | S15: =IFERROR(AVERAGE(F15:Q15), "0") -> 0
E16: Sertifikasi | F16: 0 | G16: 0 | H16: 0 | I16: 0 | J16: 0 | K16: 0 | L16: 0 | M16: 0 | N16: 0 | O16: 0 | P16: 0 | Q16: 0 | R16: =SUM(F16:Q16) -> 0 | S16: =IFERROR(AVERAGE(F16:Q16), "0") -> 0
E17: TOEFL / TOEIC | F17: 0 | G17: 0 | H17: 0 | I17: 0 | J17: 0 | K17: 0 | L17: 0 | M17: 0 | N17: 0 | O17: 0 | P17: 0 | Q17: 0 | R17: =SUM(F17:Q17) -> 0 | S17: =IFERROR(AVERAGE(F17:Q17), "0") -> 0
E18: Denda KHS / KRS | F18: 0 | G18: 0 | H18: 0 | I18: 0 | J18: 0 | K18: 0 | L18: 0 | M18: 0 | N18: 0 | O18: 0 | P18: 0 | Q18: 0 | R18: =SUM(F18:Q18) -> 0 | S18: =IFERROR(AVERAGE(F18:Q18), "0") -> 0
E19: Pendapatan Matrikulasi | F19: 0 | G19: 0 | H19: 0 | I19: 0 | J19: 0 | K19: 0 | L19: 0 | M19: 0 | N19: 0 | O19: 0 | P19: 0 | Q19: 0 | R19: =SUM(F19:Q19) -> 0 | S19: =IFERROR(AVERAGE(F19:Q19), "0") -> 0
E20: Kegiatan Kemahasiswaan | F20: 0 | G20: 0 | H20: 0 | I20: 0 | J20: 0 | K20: 0 | L20: 0 | M20: 0 | N20: 0 | O20: 0 | P20: 0 | Q20: 0 | R20: =SUM(F20:Q20) -> 0 | S20: =IFERROR(AVERAGE(F20:Q20), "0") -> 0
... E29: Kegiatan Proyek Kerjasama | F29: 0 | G29: 0 | H29: 0 | I29: 0 | J29: 0 | K29: 0 | L29: 0 | M29: 0 | N29: 0 | O29: 0 | P29: 0 | Q29: 0 | R29: =SUM(F29:Q29) -> 0 | S29: =IFERROR(AVERAGE(F29:Q29), "0") -> 0

Sheet Expenses
B1: UNIT / PRODI | E1: Beban | F1: 45839 | G1: 45870 | H1: 45901 | I1: 45931 | J1: 45962 | K1: 45992 | L1: 46023 | M1: 46054 | N1: 46082 | O1: 46113 | P1: 46143 | Q1: 46174 | R1: Total | S1: Average
B2: Beban Gaji | E2: Total Tahun | F2: =SUM(F3:F5) -> 0 | G2: =SUM(G3:G5) -> 0 | H2: =SUM(H3:H5) -> 0 | I2: =SUM(I3:I5) -> 0 | J2: =SUM(J3:J5) -> 0 | K2: =SUM(K3:K5) -> 0 | L2: =SUM(L3:L5) -> 0 | M2: =SUM(M3:M5) -> 0 | ... Q2: =SUM(Q3:Q5) -> 0 | R2: =SUM(F2:Q2) -> 0 | S2: =IFERROR(AVERAGE(F2:Q2), "Rp0") -> 0
E3: Gaji Dosen dan THR (sumber BAKeu) | F3: 0 | G3: 0 | H3: 0 | I3: 0 | J3: 0 | K3: 0 | L3: 0 | M3: 0 | N3: 0 | O3: 0 | P3: 0 | Q3: 0 | R3: =SUM(F3:Q3) -> 0 | S3: =IFERROR(AVERAGE(F3:Q3), "Rp0") -> 0
E4: Gaji Bersama | F4: 0 | G4: 0 | H4: 0 | I4: 0 | J4: 0 | K4: 0 | L4: 0 | M4: 0 | N4: 0 | O4: 0 | P4: 0 | Q4: 0 | R4: =SUM(F4:Q4) -> 0 | S4: =IFERROR(AVERAGE(F4:Q4), "Rp0") -> 0
B7: Beban Akademik Operasional | E7: Total Tahunan | F7: =SUM(F8:F42) -> 20000 | G7: =SUM(G8:G42) -> 0 | H7: =SUM(H8:H42) -> 0 | I7: =SUM(I8:I42) -> 0 | J7: =SUM(J8:J42) -> 0 | K7: =SUM(K8:K42) -> 0 | L7: =SUM(L8:L42) -> 0 | M7: =SUM(M8:M42) -> 0 | ... Q7: =SUM(Q8:Q42) -> 0 | R7: =SUM(F7:Q7) -> 20000 | S7: =IFERROR(AVERAGE(F7:Q7), "Rp0") -> 1666.6667
E8: Perpustakaan / Buku / Majalah | F8: 20000 | G8: 0 | H8: 0 | I8: 0 | J8: 0 | K8: 0 | L8: 0 | M8: 0 | N8: 0 | O8: 0 | P8: 0 | Q8: 0 | R8: =SUM(F8:Q8) -> 20000 | S8: =IFERROR(AVERAGE(F8:Q8), "Rp0") -> 1666.6667
E9: Raker / Rapat | F9: 0 | G9: 0 | H9: 0 | I9: 0 | J9: 0 | K9: 0 | L9: 0 | M9: 0 | N9: 0 | O9: 0 | P9: 0 | Q9: 0 | R9: =SUM(F9:Q9) -> 0 | S9: =IFERROR(AVERAGE(F9:Q9), "Rp0") -> 0
E10: Administrasi Pendidikan / Perkuliahan / FC / Jilid / Cetak | F10: 0 | G10: 0 | H10: 0 | I10: 0 | J10: 0 | K10: 0 | L10: 0 | M10: 0 | N10: 0 | O10: 0 | P10: 0 | Q10: 0 | R10: =SUM(F10:Q10) -> 0 | S10: =IFERROR(AVERAGE(F10:Q10), "Rp0") -> 0
E11: Program Jurusan / Rektorat | F11: 0 | G11: 0 | H11: 0 | I11: 0 | J11: 0 | K11: 0 | L11: 0 | M11: 0 | N11: 0 | O11: 0 | P11: 0 | Q11: 0 | R11: =SUM(F11:Q11) -> 0 | S11: =IFERROR(AVERAGE(F11:Q11), "Rp0") -> 0
E12: Akreditasi (Jurusan) | F12: 0 | G12: 0 | H12: 0 | I12: 0 | J12: 0 | K12: 0 | L12: 0 | M12: 0 | N12: 0 | O12: 0 | P12: 0 | Q12: 0 | R12: =SUM(F12:Q12) -> 0 | S12: =IFERROR(AVERAGE(F12:Q12), "Rp0") -> 0
E13: Peralatan/ Alat Peraga | F13: 0 | G13: 0 | H13: 0 | I13: 0 | J13: 0 | K13: 0 | L13: 0 | M13: 0 | N13: 0 | O13: 0 | P13: 0 | Q13: 0 | R13: =SUM(F13:Q13) -> 0 | S13: =IFERROR(AVERAGE(F13:Q13), "Rp0") -> 0
E14: Laboratorium / Pengelolaan Laboratorium | F14: 0 | G14: 0 | H14: 0 | I14: 0 | J14: 0 | K14: 0 | L14: 0 | M14: 0 | N14: 0 | O14: 0 | P14: 0 | Q14: 0 | R14: =SUM(F14:Q14) -> 0 | S14: =IFERROR(AVERAGE(F14:Q14), "Rp0") -> 0
E15: Iuran Aptisi/ Keanggotaan | F15: 0 | G15: 0 | H15: 0 | I15: 0 | J15: 0 | K15: 0 | L15: 0 | M15: 0 | N15: 0 | O15: 0 | P15: 0 | Q15: 0 | R15: =SUM(F15:Q15) -> 0 | S15: =IFERROR(AVERAGE(F15:Q15), "Rp0") -> 0
E16: Lain-Lain Akademik | F16: 0 | G16: 0 | H16: 0 | I16: 0 | J16: 0 | K16: 0 | L16: 0 | M16: 0 | N16: 0 | O16: 0 | P16: 0 | Q16: 0 | R16: =SUM(F16:Q16) -> 0 | S16: =IFERROR(AVERAGE(F16:Q16), "Rp0") -> 0
E17: Seminar / Pelatihan / Studium Generalle | F17: 0 | G17: 0 | H17: 0 | I17: 0 | J17: 0 | K17: 0 | L17: 0 | M17: 0 | N17: 0 | O17: 0 | P17: 0 | Q17: 0 | R17: =SUM(F17:Q17) -> 0 | S17: =IFERROR(AVERAGE(F17:Q17), "Rp0") -> 0
E18: Perlengkapan Pengajaran / ATK Pengajaran | F18: 0 | G18: 0 | H18: 0 | I18: 0 | J18: 0 | K18: 0 | L18: 0 | M18: 0 | N18: 0 | O18: 0 | P18: 0 | Q18: 0 | R18: =SUM(F18:Q18) -> 0 | S18: =IFERROR(AVERAGE(F18:Q18), "Rp0") -> 0
E19: Penulisan Buku / Pemakalah | F19: 0 | G19: 0 | H19: 0 | I19: 0 | J19: 0 | K19: 0 | L19: 0 | M19: 0 | N19: 0 | O19: 0 | P19: 0 | Q19: 0 | R19: =SUM(F19:Q19) -> 0 | S19: =IFERROR(AVERAGE(F19:Q19), "Rp0") -> 0
E20: Biaya Internet | F20: 0 | G20: 0 | H20: 0 | I20: 0 | J20: 0 | K20: 0 | L20: 0 | M20: 0 | N20: 0 | O20: 0 | P20: 0 | Q20: 0 | R20: =SUM(F20:Q20) -> 0 | S20: =IFERROR(AVERAGE(F20:Q20), "Rp0") -> 0
A21: =#REF!+#REF!+#REF! -> #REF! | E21: Biaya Sevima | F21: 0 | G21: 0 | H21: 0 | I21: 0 | J21: 0 | K21: 0 | L21: 0 | M21: 0 | N21: 0 | O21: 0 | P21: 0 | Q21: 0 | R21: =SUM(F21:Q21) -> 0 | S21: =IFERROR(AVERAGE(F21:Q21), "Rp0") -> 0
E22: Biaya Penelitian | F22: 0 | G22: 0 | H22: 0 | I22: 0 | J22: 0 | K22: 0 | L22: 0 | M22: 0 | N22: 0 | O22: 0 | P22: 0 | Q22: 0 | R22: =SUM(F22:Q22) -> 0 | S22: =IFERROR(AVERAGE(F22:Q22), "Rp0") -> 0
E23: Campus Agreement/ MOU Prodi | F23: 0 | G23: 0 | H23: 0 | I23: 0 | J23: 0 | K23: 0 | L23: 0 | M23: 0 | N23: 0 | O23: 0 | P23: 0 | Q23: 0 | R23: =SUM(F23:Q23) -> 0 | S23: =IFERROR(AVERAGE(F23:Q23), "Rp0") -> 0
E24: Biaya Kegiatan Wisuda | F24: 0 | G24: 0 | H24: 0 | I24: 0 | J24: 0 | K24: 0 | L24: 0 | M24: 0 | N24: 0 | O24: 0 | P24: 0 | Q24: 0 | R24: =SUM(F24:Q24) -> 0 | S24: =IFERROR(AVERAGE(F24:Q24), "Rp0") -> 0
E25: Biaya Kegiatan Sertifikasi | F25: 0 | G25: 0 | H25: 0 | I25: 0 | J25: 0 | K25: 0 | L25: 0 | M25: 0 | N25: 0 | O25: 0 | P25: 0 | Q25: 0 | R25: =SUM(F25:Q25) -> 0 | S25: =IFERROR(AVERAGE(F25:Q25), "Rp0") -> 0
E26: Beban Kegiatan KKN | F26: 0 | G26: 0 | H26: 0 | I26: 0 | J26: 0 | K26: 0 | L26: 0 | M26: 0 | N26: 0 | O26: 0 | P26: 0 | Q26: 0 | R26: =SUM(F26:Q26) -> 0 | S26: =IFERROR(AVERAGE(F26:Q26), "Rp0") -> 0
E27: Beban Kegiatan Ekskursi / Studi Tour/ Kuliah Lapangan | F27: 0 | G27: 0 | H27: 0 | I27: 0 | J27: 0 | K27: 0 | L27: 0 | M27: 0 | N27: 0 | O27: 0 | P27: 0 | Q27: 0 | R27: =SUM(F27:Q27) -> 0 | S27: =IFERROR(AVERAGE(F27:Q27), "Rp0") -> 0
E28: Beban Kegiatan UPMB / PEMBA | F28: 0 | G28: 0 | H28: 0 | I28: 0 | J28: 0 | K28: 0 | L28: 0 | M28: 0 | N28: 0 | O28: 0 | P28: 0 | Q28: 0 | R28: =SUM(F28:Q28) -> 0 | S28: =IFERROR(AVERAGE(F28:Q28), "Rp0") -> 0
E29: Beban Visa / Ijin & Lain Native | F29: 0 | G29: 0 | H29: 0 | I29: 0 | J29: 0 | K29: 0 | L29: 0 | M29: 0 | N29: 0 | O29: 0 | P29: 0 | Q29: 0 | R29: =SUM(F29:Q29) -> 0 | S29: =IFERROR(AVERAGE(F29:Q29), "Rp0") -> 0
E30: Beban Kegiatan UAS / UTS | F30: 0 | G30: 0 | H30: 0 | I30: 0 | J30: 0 | K30: 0 | L30: 0 | M30: 0 | N30: 0 | O30: 0 | P30: 0 | Q30: 0 | R30: =SUM(F30:Q30) -> 0 | S30: =IFERROR(AVERAGE(F30:Q30), "Rp0") -> 0
E31: Beban Kegiatan Sidang / Sidang Ulang TA & Proposal TA (7 mahasiswa) | F31: 0 | G31: 0 | H31: 0 | I31: 0 | J31: 0 | K31: 0 | L31: 0 | M31: 0 | N31: 0 | O31: 0 | P31: 0 | Q31: 0 | R31: =SUM(F31:Q31) -> 0 | S31: =IFERROR(AVERAGE(F31:Q31), "Rp0") -> 0
E32: Beban Kegiatan Psikotest | F32: 0 | G32: 0 | H32: 0 | I32: 0 | J32: 0 | K32: 0 | L32: 0 | M32: 0 | N32: 0 | O32: 0 | P32: 0 | Q32: 0 | R32: =SUM(F32:Q32) -> 0 | S32: =IFERROR(AVERAGE(F32:Q32), "Rp0") -> 0
E33: Beban Kegiatan Pembuatan KTM | F33: 0 | G33: 0 | H33: 0 | I33: 0 | J33: 0 | K33: 0 | L33: 0 | M33: 0 | N33: 0 | O33: 0 | P33: 0 | Q33: 0 | R33: =SUM(F33:Q33) -> 0 | S33: =IFERROR(AVERAGE(F33:Q33), "Rp0") -> 0
... E42: Beban Kerjasama | F42: 0 | G42: 0 | H42: 0 | I42: 0 | J42: 0 | K42: 0 | L42: 0 | M42: 0 | N42: 0 | O42: 0 | P42: 0 | Q42: 0 | R42: =SUM(F42:Q42) -> 0 | S42: =IFERROR(AVERAGE(F42:Q42), "Rp0") -> 0
B45: Beban Kantor Umum | E45: Total Bulanan: | F45: =SUM(F46:F68) -> 0 | G45: =SUM(G46:G68) -> 0 | H45: =SUM(H46:H68) -> 0 | I45: =SUM(I46:I68) -> 0 | J45: =SUM(J46:J68) -> 0 | K45: =SUM(K46:K68) -> 0 | L45: =SUM(L46:L68) -> 0 | M45: =SUM(M46:M68) -> 0 | ... Q45: =SUM(Q46:Q68) -> 0 | R45: =SUM(F45:Q45) -> 0 | S45: =IFERROR(AVERAGE(F45:Q45), "Rp0") -> 0
E46: ATK & Benda Pos | F46: 0 | G46: 0 | H46: 0 | I46: 0 | J46: 0 | K46: 0 | L46: 0 | M46: 0 | N46: 0 | O46: 0 | P46: 0 | Q46: 0 | R46: =SUM(F46:Q46) -> 0 | S46: =IFERROR(AVERAGE(F46:Q46), "Rp0") -> 0
E47: PDAM | F47: 0 | G47: 0 | H47: 0 | I47: 0 | J47: 0 | K47: 0 | L47: 0 | M47: 0 | N47: 0 | O47: 0 | P47: 0 | Q47: 0 | R47: =SUM(F47:Q47) -> 0 | S47: =IFERROR(AVERAGE(F47:Q47), "Rp0") -> 0
E48: PLN / Listrik | F48: 0 | G48: 0 | H48: 0 | I48: 0 | J48: 0 | K48: 0 | L48: 0 | M48: 0 | N48: 0 | O48: 0 | P48: 0 | Q48: 0 | R48: =SUM(F48:Q48) -> 0 | S48: =IFERROR(AVERAGE(F48:Q48), "Rp0") -> 0
E49: Telepon / Pulsa | F49: 0 | G49: 0 | H49: 0 | I49: 0 | J49: 0 | K49: 0 | L49: 0 | M49: 0 | N49: 0 | O49: 0 | P49: 0 | Q49: 0 | R49: =SUM(F49:Q49) -> 0 | S49: =IFERROR(AVERAGE(F49:Q49), "Rp0") -> 0
E50: Koran | F50: 0 | G50: 0 | H50: 0 | I50: 0 | J50: 0 | K50: 0 | L50: 0 | M50: 0 | N50: 0 | O50: 0 | P50: 0 | Q50: 0 | R50: =SUM(F50:Q50) -> 0 | S50: =IFERROR(AVERAGE(F50:Q50), "Rp0") -> 0
E51: Sumbangan / Pernikahan / Uang Duka | F51: 0 | G51: 0 | H51: 0 | I51: 0 | J51: 0 | K51: 0 | L51: 0 | M51: 0 | N51: 0 | O51: 0 | P51: 0 | Q51: 0 | R51: =SUM(F51:Q51) -> 0 | S51: =IFERROR(AVERAGE(F51:Q51), "Rp0") -> 0
E52: Iuran RT | F52: 0 | G52: 0 | H52: 0 | I52: 0 | J52: 0 | K52: 0 | L52: 0 | M52: 0 | N52: 0 | O52: 0 | P52: 0 | Q52: 0 | R52: =SUM(F52:Q52) -> 0 | S52: =IFERROR(AVERAGE(F52:Q52), "Rp0") -> 0
...

Sheet Summary
D1: About this sheet | L1: Note
D2: This sheet generates a summary of your spending based on data in the 'Expenses' and 'Income' tabs. | L2: Please don't edit this sheet.
D3: Make sure you've set a starting balance in the 'Configure' tab before beginning. | L3: It contains formulas and will update automatically.
D19: Summary
E20: =Expenses!F1 -> 45839 | F20: =Expenses!G1 -> 45870 | G20: =Expenses!H1 -> 45901 | H20: =Expenses!I1 -> 45931 | I20: =Expenses!J1 -> 45962 | J20: =Expenses!K1 -> 45992 | K20: =Expenses!L1 -> 46023 | L20: =Expenses!M1 -> 46054 | ... P20: =Expenses!Q1 -> 46174 | Q20: =Expenses!#REF! -> #REF! | R20: =Expenses!#REF! -> #REF! | S20: =Expenses!#REF! -> #REF! | T20: =Expenses!#REF! -> #REF! | U20: =Expenses!#REF! -> #REF! | V20: =Expenses!#REF! -> #REF! | W20: =Expenses!#REF! -> #REF! | X20: =Expenses!#REF! -> #REF! | Y20: Total | Z20: Rata-Rata
D21: Income | E21: =+Income!F2 -> 0 | F21: =SUM(F28:F30) -> 0 | G21: =SUM(G28:G30) -> 0 | H21: =SUM(H28:H30) -> 0 | I21: =SUM(I28:I30) -> 0 | J21: =SUM(J28:J30) -> 0 | K21: =SUM(K28:K30) -> 0 | L21: =SUM(L28:L30) -> 0 | M21: =SUM(M28:M30) -> 0 | ... Z21: =SUM(Z28:Z30) -> 0
D22: Expenses | E22: =SUM(E33:E42) -> 20000 | F22: =SUM(F33:F42) -> 0 | G22: =SUM(G33:G42) -> 0 | H22: =SUM(H33:H42) -> 0 | I22: =SUM(I33:I42) -> 0 | J22: =SUM(J33:J42) -> 0 | K22: =SUM(K33:K42) -> 0 | L22: =SUM(L33:L42) -> 0 | ... N22: =SUM(N33:N42) -> 0 | O22: =Expenses!P7+Expenses!P45 -> 0 | P22: =SUM(P33:P42) -> 0 | Q22: =SUM(Q33:Q42) -> #REF! | R22: =SUM(R33:R42) -> #REF! | S22: =SUM(S33:S42) -> #REF! | T22: =SUM(T33:T42) -> #REF! | U22: =SUM(U33:U42) -> #REF! | V22: =SUM(V33:V42) -> #REF! | W22: =SUM(W33:W42) -> #REF! | ... Z22: =SUM(Z33:Z42) -> 1666.6667
D23: Net savings | E23: =E21-E22 -> -20000 | F23: =F21-F22 -> 0 | G23: =G21-G22 -> 0 | H23: =H21-H22 -> 0 | I23: =I21-I22 -> 0 | J23: =J21-J22 -> 0 | K23: =K21-K22 -> 0 | L23: =L21-L22 -> 0 | ... Z23: =Z21-Z22 -> -1666.6667
D24: Ending balance | E24: =(Balance+E21)-E22 -> -20000 | F24: =(Balance+F21)-F22 -> 0 | G24: =(Balance+G21)-G22 -> 0 | H24: =(Balance+H21)-H22 -> 0 | I24: =(Balance+I21)-I22 -> 0 | J24: =(Balance+J21)-J22 -> 0 | K24: =(Balance+K21)-K22 -> 0 | L24: =(Balance+L21)-L22 -> 0 | ... Z24: =(Balance+Z21)-Z22 -> -1666.6667
D26: Pendapatan
B27: Row # | D27: =IFERROR(__xludf.DUMMYFUNCTION("unique(Income!B:B)"),"") | E27: =+Income!F1 -> 45839 | F27: =+Income!G1 -> 45870 | G27: =+Income!H1 -> 45901 | H27: =+Income!I1 -> 45931 | I27: =+Income!J1 -> 45962 | J27: =+Income!K1 -> 45992 | K27: =+Income!L1 -> 46023 | L27: =+Income!M1 -> 46054 | ... P27: =+Income!Q1 -> 46174 | Q27: =+Income!#REF! -> #REF! | R27: =+Income!#REF! -> #REF! | S27: =+Income!#REF! -> #REF! | T27: =+Income!#REF! -> #REF! | U27: =+Income!#REF! -> #REF! | V27: =+Income!#REF! -> #REF! | W27: =+Income!#REF! -> #REF! | X27: =+Income!#REF! -> #REF! | Y27: Total | Z27: Rata-Rata
B28: 2 | D28: =IFERROR(__xludf.DUMMYFUNCTION("""COMPUTED_VALUE"""),"Pendapatan Operasional") -> Pendapatan Operasional | E28: =+Income!F2 -> 0 | F28: =+Income!G2 -> 0 | G28: =+Income!H2 -> 0 | H28: =+Income!I2 -> 0 | I28: =+Income!J2 -> 0 | J28: =+Income!K2 -> 0 | K28: =+Income!L2 -> 0 | L28: =+Income!M2 -> 0 | ... P28: =+Income!Q2 -> 0 | Q28: =+Income!#REF! -> #REF! | R28: =+Income!#REF! -> #REF! | S28: =+Income!#REF! -> #REF! | T28: =+Income!#REF! -> #REF! | U28: =+Income!#REF! -> #REF! | V28: =+Income!#REF! -> #REF! | W28: =+Income!#REF! -> #REF! | X28: =+Income!#REF! -> #REF! | Y28: =+Income!R2 -> 0 | Z28: =+Income!S2 -> 0
B29: 8 | D29: =IFERROR(__xludf.DUMMYFUNCTION("""COMPUTED_VALUE"""),"Pendapatan Lain-Lain") -> Pendapatan Lain-Lain | E29: =+Income!F8 -> 0 | F29: =+Income!G8 -> 0 | G29: =+Income!H8 -> 0 | H29: =+Income!I8 -> 0 | I29: =+Income!J8 -> 0 | J29: =+Income!K8 -> 0 | K29: =+Income!L8 -> 0 | L29: =+Income!M8 -> 0 | ... P29: =+Income!Q8 -> 0 | Q29: =+Income!#REF! -> #REF! | R29: =+Income!#REF! -> #REF! | S29: =+Income!#REF! -> #REF! | T29: =+Income!#REF! -> #REF! | U29: =+Income!#REF! -> #REF! | V29: =+Income!#REF! -> #REF! | W29: =+Income!#REF! -> #REF! | X29: =+Income!#REF! -> #REF! | Y29: =+Income!R8 -> 0 | Z29: =+Income!S8 -> 0
D31: Beban
B32: Row # | D32: =IFERROR(__xludf.DUMMYFUNCTION("unique(Expenses!B:B)"),"") | E32: =+Income!F1 -> 45839 | F32: =+Income!G1 -> 45870 | G32: =+Income!H1 -> 45901 | H32: =+Income!I1 -> 45931 | I32: =+Income!J1 -> 45962 | J32: =+Income!K1 -> 45992 | K32: =+Income!L1 -> 46023 | L32: =+Income!M1 -> 46054 | ... P32: =+Income!Q1 -> 46174 | Q32: =+Expenses!#REF! -> #REF! | R32: =+Expenses!#REF! -> #REF! | S32: =+Expenses!#REF! -> #REF! | T32: =+Expenses!#REF! -> #REF! | U32: =+Expenses!#REF! -> #REF! | V32: =+Expenses!#REF! -> #REF! | W32: =+Expenses!#REF! -> #REF! | X32: =+Expenses!#REF! -> #REF! | Y32: Total | Z32: Rata-Rata
B33: 2 | D33: =IFERROR(__xludf.DUMMYFUNCTION("""COMPUTED_VALUE"""),"Beban Gaji") -> Beban Gaji | E33: =Expenses!F2 -> 0 | F33: =Expenses!G2 -> 0 | G33: =Expenses!H2 -> 0 | H33: =Expenses!I2 -> 0 | I33: =Expenses!J2 -> 0 | J33: =Expenses!K2 -> 0 | K33: =Expenses!L2 -> 0 | L33: =Expenses!M2 -> 0 | ... P33: =Expenses!Q2 -> 0 | Q33: =Expenses!#REF! -> #REF! | R33: =Expenses!#REF! -> #REF! | S33: =Expenses!#REF! -> #REF! | T33: =Expenses!#REF! -> #REF! | U33: =Expenses!#REF! -> #REF! | V33: =Expenses!#REF! -> #REF! | W33: =Expenses!#REF! -> #REF! | X33: =Expenses!#REF! -> #REF! | Y33: =Expenses!R2 -> 0 | Z33: =Expenses!S2 -> 0
B34: 7 | D34: =IFERROR(__xludf.DUMMYFUNCTION("""COMPUTED_VALUE"""),"Beban Akademik Operasional") -> Beban Akademik Operasional | E34: =Expenses!F7 -> 20000 | F34: =Expenses!G7 -> 0 | G34: =Expenses!H7 -> 0 | H34: =Expenses!I7 -> 0 | I34: =Expenses!J7 -> 0 | J34: =Expenses!K7 -> 0 | K34: =Expenses!L7 -> 0 | L34: =Expenses!M7 -> 0 | ... P34: =Expenses!Q7 -> 0 | Q34: =Expenses!#REF! -> #REF! | R34: =Expenses!#REF! -> #REF! | S34: =Expenses!#REF! -> #REF! | T34: =Expenses!#REF! -> #REF! | U34: =Expenses!#REF! -> #REF! | V34: =Expenses!#REF! -> #REF! | W34: =Expenses!#REF! -> #REF! | X34: =Expenses!#REF! -> #REF! | Y34: =Expenses!R7 -> 20000 | Z34: =Expenses!S7 -> 1666.6667
B35: 45 | D35: =IFERROR(__xludf.DUMMYFUNCTION("""COMPUTED_VALUE"""),"Beban Kantor Umum") -> Beban Kantor Umum | E35: =Expenses!F45 -> 0 | F35: =Expenses!G45 -> 0 | G35: =Expenses!H45 -> 0 | H35: =Expenses!I45 -> 0 | I35: =Expenses!J45 -> 0 | J35: =Expenses!K45 -> 0 | K35: =Expenses!L45 -> 0 | L35: =Expenses!M45 -> 0 | ... P35: =Expenses!Q45 -> 0 | Q35: =Expenses!#REF! -> #REF! | R35: =Expenses!#REF! -> #REF! | S35: =Expenses!#REF! -> #REF! | T35: =Expenses!#REF! -> #REF! | U35: =Expenses!#REF! -> #REF! | V35: =Expenses!#REF! -> #REF! | W35: =Expenses!#REF! -> #REF! | X35: =Expenses!#REF! -> #REF! | Y35: =Expenses!R45 -> 0 | Z35: =Expenses!S45 -> 0
B36: 71 | D36: =IFERROR(__xludf.DUMMYFUNCTION("""COMPUTED_VALUE"""),"Beban Pemeliharaan") -> Beban Pemeliharaan | E36: =Expenses!F71 -> 0 | F36: =Expenses!G71 -> 0 | G36: =Expenses!H71 -> 0 | H36: =Expenses!I71 -> 0 | I36: =Expenses!J71 -> 0 | J36: =Expenses!K71 -> 0 | K36: =Expenses!L71 -> 0 | L36: =Expenses!M71 -> 0 | ... P36: =Expenses!Q71 -> 0 | Q36: =Expenses!#REF! -> #REF! | R36: =Expenses!#REF! -> #REF! | S36: =Expenses!#REF! -> #REF! | T36: =Expenses!#REF! -> #REF! | U36: =Expenses!#REF! -> #REF! | V36: =Expenses!#REF! -> #REF! | W36: =Expenses!#REF! -> #REF! | X36: =Expenses!#REF! -> #REF! | Y36: =Expenses!R71 -> 0 | Z36: =Expenses!S71 -> 0
B37: 79 | D37: =IFERROR(__xludf.DUMMYFUNCTION("""COMPUTED_VALUE"""),"Beban Marketing") -> Beban Marketing | E37: =Expenses!F79 -> 0 | F37: =Expenses!G79 -> 0 | G37: =Expenses!H79 -> 0 | H37: =Expenses!I79 -> 0 | I37: =Expenses!J79 -> 0 | J37: =Expenses!K79 -> 0 | K37: =Expenses!L79 -> 0 | L37: =Expenses!M79 -> 0 | ... P37: =Expenses!Q79 -> 0 | Q37: =Expenses!#REF! -> #REF! | R37: =Expenses!#REF! -> #REF! | S37: =Expenses!#REF! -> #REF! | T37: =Expenses!#REF! -> #REF! | U37: =Expenses!#REF! -> #REF! | V37: =Expenses!#REF! -> #REF! | W37: =Expenses!#REF! -> #REF! | X37: =Expenses!#REF! -> #REF! | Y37: =Expenses!R79 -> 0 | Z37: =Expenses!S79 -> 0
B38: 84 | D38: =IFERROR(__xludf.DUMMYFUNCTION("""COMPUTED_VALUE"""),"Beban Asuransi") -> Beban Asuransi | E38: =Expenses!F84 -> 0 | F38: =Expenses!G84 -> 0 | G38: =Expenses!H84 -> 0 | H38: =Expenses!I84 -> 0 | I38: =Expenses!J84 -> 0 | J38: =Expenses!K84 -> 0 | K38: =Expenses!L84 -> 0 | L38: =Expenses!M84 -> 0 | ... P38: =Expenses!Q84 -> 0 | Q38: =Expenses!#REF! -> #REF! | R38: =Expenses!#REF! -> #REF! | S38: =Expenses!#REF! -> #REF! | T38: =Expenses!#REF! -> #REF! | U38: =Expenses!#REF! -> #REF! | V38: =Expenses!#REF! -> #REF! | W38: =Expenses!#REF! -> #REF! | X38: =Expenses!#REF! -> #REF! | Y38: =Expenses!R84 -> 0 | Z38: =Expenses!S84 -> 0
B39: 89 | D39: =IFERROR(__xludf.DUMMYFUNCTION("""COMPUTED_VALUE"""),"Beban Penghapusan Piutang Mahasiswa") -> Beban Penghapusan Piutang Mahasiswa | E39: =Expenses!F89 -> 0 | F39: =Expenses!G89 -> 0 | G39: =Expenses!H89 -> 0 | H39: =Expenses!I89 -> 0 | I39: =Expenses!J89 -> 0 | J39: =Expenses!K89 -> 0 | K39: =Expenses!L89 -> 0 | L39: =Expenses!M89 -> 0 | ... P39: =Expenses!Q89 -> 0 | Q39: =Expenses!#REF! -> #REF! | R39: =Expenses!#REF! -> #REF! | S39: =Expenses!#REF! -> #REF! | T39: =Expenses!#REF! -> #REF! | U39: =Expenses!#REF! -> #REF! | V39: =Expenses!#REF! -> #REF! | W39: =Expenses!#REF! -> #REF! | X39: =Expenses!#REF! -> #REF! | Y39: =Expenses!R89 -> 0 | Z39: =Expenses!S89 -> 0
B40: 93 | D40: =IFERROR(__xludf.DUMMYFUNCTION("""COMPUTED_VALUE"""),"Beban Sertifikasi & Proyek lainnya") -> Beban Sertifikasi & Proyek lainnya | E40: =Expenses!F93 -> 0 | F40: =Expenses!G93 -> 0 | G40: =Expenses!H93 -> 0 | H40: =Expenses!I93 -> 0 | I40: =Expenses!J93 -> 0 | J40: =Expenses!K93 -> 0 | K40: =Expenses!L93 -> 0 | L40: =Expenses!M93 -> 0 | ... P40: =Expenses!Q93 -> 0 | Q40: =Expenses!#REF! -> #REF! | R40: =Expenses!#REF! -> #REF! | S40: =Expenses!#REF! -> #REF! | T40: =Expenses!#REF! -> #REF! | U40: =Expenses!#REF! -> #REF! | V40: =Expenses!#REF! -> #REF! | W40: =Expenses!#REF! -> #REF! | X40: =Expenses!#REF! -> #REF! | Y40: =Expenses!R93 -> 0 | Z40: =Expenses!S93 -> 0
B41: 97 | D41: =IFERROR(__xludf.DUMMYFUNCTION("""COMPUTED_VALUE"""),"Beban Pasca Kerja") -> Beban Pasca Kerja | E41: =Expenses!F97 -> 0 | F41: =Expenses!G97 -> 0 | G41: =Expenses!H97 -> 0 | H41: =Expenses!I97 -> 0 | I41: =Expenses!J97 -> 0 | J41: =Expenses!K97 -> 0 | K41: =Expenses!L97 -> 0 | L41: =Expenses!M97 -> 0 | ... P41: =Expenses!Q97 -> 0 | Q41: =Expenses!#REF! -> #REF! | R41: =Expenses!#REF! -> #REF! | S41: =Expenses!#REF! -> #REF! | T41: =Expenses!#REF! -> #REF! | U41: =Expenses!#REF! -> #REF! | V41: =Expenses!#REF! -> #REF! | W41: =Expenses!#REF! -> #REF! | X41: =Expenses!#REF! -> #REF! | Y41: =Expenses!R97 -> 0 | Z41: =Expenses!S97 -> 0
B42: 100 | D42: =IFERROR(__xludf.DUMMYFUNCTION("""COMPUTED_VALUE"""),"Beban Cadangan Pensiun & THR") -> Beban Cadangan Pensiun & THR | E42: =Expenses!F101 -> 0 | F42: =Expenses!G101 -> 0 | G42: =Expenses!H101 -> 0 | H42: =Expenses!I101 -> 0 | I42: =Expenses!J101 -> 0 | J42: =Expenses!K101 -> 0 | K42: =Expenses!L101 -> 0 | L42: =Expenses!M101 -> 0 | ... P42: =Expenses!Q101 -> 0 | Q42: =Expenses!#REF! -> #REF! | R42: =Expenses!#REF! -> #REF! | S42: =Expenses!#REF! -> #REF! | T42: =Expenses!#REF! -> #REF! | U42: =Expenses!#REF! -> #REF! | V42: =Expenses!#REF! -> #REF! | W42: =Expenses!#REF! -> #REF! | X42: =Expenses!#REF! -> #REF! | Y42: =Expenses!R101 -> 0 | Z42: =Expenses!S101 -> 0
B43: 106 | D43: =IFERROR(__xludf.DUMMYFUNCTION("""COMPUTED_VALUE"""),"Beban Penyusutan") -> Beban Penyusutan | E43: =Expenses!F107 -> 0 | F43: =Expenses!G107 -> 0 | G43: =Expenses!H107 -> 0 | H43: =Expenses!I107 -> 0 | I43: =Expenses!J107 -> 0 | J43: =Expenses!K107 -> 0 | K43: =Expenses!L107 -> 0 | L43: =Expenses!M107 -> 0 | ... P43: =Expenses!Q107 -> 0 | Q43: =Expenses!#REF! -> #REF! | R43: =Expenses!#REF! -> #REF! | S43: =Expenses!#REF! -> #REF! | T43: =Expenses!#REF! -> #REF! | U43: =Expenses!#REF! -> #REF! | V43: =Expenses!#REF! -> #REF! | W43: =Expenses!#REF! -> #REF! | X43: =Expenses!#REF! -> #REF! | Y43: =Expenses!R107 -> 0 | Z43: =Expenses!S107 -> 0 | AA43: =SUM(G43:Z43) -> #REF!
B44: 111 | D44: =IFERROR(__xludf.DUMMYFUNCTION("""COMPUTED_VALUE"""),"Pengeluaran Hibah") -> Pengeluaran Hibah | E44: =Expenses!F112 -> 0 | F44: =Expenses!G112 -> 0 | G44: =Expenses!H112 -> 0 | H44: =Expenses!I112 -> 0 | I44: =Expenses!J112 -> 0 | J44: =Expenses!K112 -> 0 | K44: =Expenses!L112 -> 0 | L44: =Expenses!M112 -> 0 | ... P44: =Expenses!Q112 -> 0 | Q44: =Expenses!#REF! -> #REF! | R44: =Expenses!#REF! -> #REF! | S44: =Expenses!#REF! -> #REF! | T44: =Expenses!#REF! -> #REF! | U44: =Expenses!#REF! -> #REF! | V44: =Expenses!#REF! -> #REF! | W44: =Expenses!#REF! -> #REF! | X44: =Expenses!#REF! -> #REF! | Y44: =Expenses!R112 -> 0 | Z44: =Expenses!S112 -> 0
E45: =IF(NOT(ISBLANK(B45)), INDIRECT("Expenses!D"&B45&":Q"&B45),"")
E46: =IF(NOT(ISBLANK(B46)), INDIRECT("Expenses!D"&B46&":Q"&B46),"")
E47: =IF(NOT(ISBLANK(B47)), INDIRECT("Expenses!D"&B47&":Q"&B47),"")
E48: =IF(NOT(ISBLANK(B48)), INDIRECT("Expenses!D"&B48&":Q"&B48),"")
E49: =IF(NOT(ISBLANK(B49)), INDIRECT("Expenses!D"&B49&":Q"&B49),"")
E50: =IF(NOT(ISBLANK(B50)), INDIRECT("Expenses!D"&B50&":Q"&B50),"")
E51: =IF(NOT(ISBLANK(B51)), INDIRECT("Expenses!D"&B51&":Q"&B51),"")
E52: =IF(NOT(ISBLANK(B52)), INDIRECT("Expenses!D"&B52&":Q"&B52),"")
E53: =IF(NOT(ISBLANK(B53)), INDIRECT("Expenses!D"&B53&":Q"&B53),"")
E54: =IF(NOT(ISBLANK(B54)), INDIRECT("Expenses!D"&B54&":Q"&B54),"")
E55: =IF(NOT(ISBLANK(B55)), INDIRECT("Expenses!D"&B55&":Q"&B55),"")
E56: =IF(NOT(ISBLANK(B56)), INDIRECT("Expenses!D"&B56&":Q"&B56),"")
... E60: =IF(NOT(ISBLANK(B60)), INDIRECT("Expenses!D"&B60&":Q"&B60),"")
